The error occurs because the `rename` function from the `std::fs` module returns a result of type `Result<(), Error>`, whereas the test functions expect a `Result<bool, io::Error>`. The solution is to use the `rename` function with `Ok(())` as it will always return a boolean indicating whether the operation was successful or not.

Here's how to rewrite the code:
```rust
use std::fs;
use std::io;

fn rename_file(oldname: &str, newname: &str) -> Result<bool, io::Error> {
    fs::rename(oldname, newname).map(|_| true)
}

fn test(type_: &str, oldname: &str, newname: &str) {
    match rename_file(oldname, newname) {
        Ok(_)  => println!(
             "The following  {} called  {} was renamed as  {}.",
            type_, oldname, newname
         ),
        Err(e)  => eprintln!("There was an error renaming the file or directory:  {}", e),
     }
}

fn main() {
    test("file",  "input.txt",  "output.txt");
    test("file",  "/input.txt",  "/output.txt");
    test("directory",  "docs",  "mydocs");
    test("directory",  "/docs/",  "/mydocs/");
}
```
